 DB_BACKEND=postgresql+psycopg2
 DB_HOST=postgres
 DB_PORT=5432
 
 [2025-01-29 14:17:19,722] {cli_action_loggers.py:107} WARNING - Failed to log action with (psycopg2.errors.UndefinedTable) relation "log" does not exist
 LINE 1: INSERT INTO log (dttm, dag_id, task_id, event, execution_dat...
                     ^
 
 [SQL: INSERT INTO log (dttm, dag_id, task_id, event, execution_date, owner, extra) VALUES (%(dttm)s, %(dag_id)s, %(task_id)s, %(event)s, %(execution_date)s, %(owner)s, %(extra)s) RETURNING log.id]
 [parameters: {'dttm': datetime.datetime(2025, 1, 29, 14, 17, 19, 670826, tzinfo=<Timezone [UTC]>), 'dag_id': None, 'task_id': None, 'event': 'cli_webserver', 'execution_date': None, 'owner': 'airflow', 'extra': '{"host_name": "91029a80010c", "full_command": "[\'/home/airflow/.local/bin/airflow\', \'webserver\']"}'}]
 (Background on this error at: http://sqlalche.me/e/f405)
   ____________       _____________
  ____    |__( )_________  __/__  /________      __
 ____  /| |_  /__  ___/_  /_ __  /_  __ \_ | /| / /
 ___  ___ |  / _  /   _  __/ _  / / /_/ /_ |/ |/ /
  _/_/  |_/_/  /_/    /_/    /_/  \____/____/|__/
 [2025-01-29 14:17:19,782] {__init__.py:51} INFO - Using executor CeleryExecutor
 [2025-01-29 14:17:19,785] {dagbag.py:396} INFO - Filling up the DagBag from /opt/airflow/dags
 [2025-01-29 14:17:19,875] {dagbag.py:239} ERROR - Failed to import: /home/airflow/.local/lib/python3.6/site-packages/airflow/example_dags/example_subdag_operator.py
 Traceback (most recent call last):
   File "/home/airflow/.local/lib/python3.6/site-packages/sqlalchemy/engine/base.py", line 1248, in _execute_context
     cursor, statement, parameters, context
   File "/home/airflow/.local/lib/python3.6/site-packages/sqlalchemy/engine/default.py", line 588, in do_execute
     cursor.execute(statement, parameters)
 psycopg2.errors.UndefinedTable: relation "slot_pool" does not exist
 LINE 2: FROM slot_pool 
              ^
 
 
 The above exception was the direct cause of the following exception:
 
 Traceback (most recent call last):
   File "/home/airflow/.local/lib/python3.6/site-packages/airflow/models/dagbag.py", line 236, in process_file
     m = imp.load_source(mod_name, filepath)
   File "/usr/local/lib/python3.6/imp.py", line 172, in load_source
     module = _load(spec)
   File "<frozen importlib._bootstrap>", line 684, in _load
   File "<frozen importlib._bootstrap>", line 665, in _load_unlocked
   File "<frozen importlib._bootstrap_external>", line 678, in exec_module
   File "<frozen importlib._bootstrap>", line 219, in _call_with_frames_removed
   File "/home/airflow/.local/lib/python3.6/site-packages/airflow/example_dags/example_subdag_operator.py", line 50, in <module>
     dag=dag,
   File "/home/airflow/.local/lib/python3.6/site-packages/airflow/utils/db.py", line 74, in wrapper
     return func(*args, **kwargs)
   File "/home/airflow/.local/lib/python3.6/site-packages/airflow/utils/decorators.py", line 98, in wrapper
     result = func(*args, **kwargs)
   File "/home/airflow/.local/lib/python3.6/site-packages/airflow/operators/subdag_operator.py", line 77, in __init__
     .filter(Pool.pool == self.pool)
   File "/home/airflow/.local/lib/python3.6/site-packages/sqlalchemy/orm/query.py", line 3298, in first
     ret = list(self[0:1])
   File "/home/airflow/.local/lib/python3.6/site-packages/sqlalchemy/orm/query.py", line 3076, in __getitem__
     return list(res)
   File "/home/airflow/.local/lib/python3.6/site-packages/sqlalchemy/orm/query.py", line 3403, in __iter__
     return self._execute_and_instances(context)
   File "/home/airflow/.local/lib/python3.6/site-packages/sqlalchemy/orm/query.py", line 3428, in _execute_and_instances
     result = conn.execute(querycontext.statement, self._params)
   File "/home/airflow/.local/lib/python3.6/site-packages/sqlalchemy/engine/base.py", line 984, in execute
     return meth(self, multiparams, params)
   File "/home/airflow/.local/lib/python3.6/site-packages/sqlalchemy/sql/elements.py", line 293, in _execute_on_connection
     return connection._execute_clauseelement(self, multiparams, params)
   File "/home/airflow/.local/lib/python3.6/site-packages/sqlalchemy/engine/base.py", line 1103, in _execute_clauseelement
     distilled_params,
   File "/home/airflow/.local/lib/python3.6/site-packages/sqlalchemy/engine/base.py", line 1288, in _execute_context
     e, statement, parameters, cursor, context
   File "/home/airflow/.local/lib/python3.6/site-packages/sqlalchemy/engine/base.py", line 1482, in _handle_dbapi_exception
     sqlalchemy_exception, with_traceback=exc_info[2], from_=e
   File "/home/airflow/.local/lib/python3.6/site-packages/sqlalchemy/util/compat.py", line 178, in raise_
     raise exception
   File "/home/airflow/.local/lib/python3.6/site-packages/sqlalchemy/engine/base.py", line 1248, in _execute_context
     cursor, statement, parameters, context
   File "/home/airflow/.local/lib/python3.6/site-packages/sqlalchemy/engine/default.py", line 588, in do_execute
     cursor.execute(statement, parameters)
 sqlalchemy.exc.ProgrammingError: (psycopg2.errors.UndefinedTable) relation "slot_pool" does not exist
 LINE 2: FROM slot_pool 
              ^
 
 [SQL: SELECT slot_pool.id AS slot_pool_id, slot_pool.pool AS slot_pool_pool, slot_pool.slots AS slot_pool_slots, slot_pool.description AS slot_pool_description 
 FROM slot_pool 
 WHERE slot_pool.slots = %(slots_1)s AND slot_pool.pool = %(pool_1)s 
  LIMIT %(param_1)s]
 [parameters: {'slots_1': 1, 'pool_1': 'default_pool', 'param_1': 1}]
 (Background on this error at: http://sqlalche.me/e/f405)
 Traceback (most recent call last):
   File "/home/airflow/.local/lib/python3.6/site-packages/sqlalchemy/engine/base.py", line 1248, in _execute_context
     cursor, statement, parameters, context
   File "/home/airflow/.local/lib/python3.6/site-packages/sqlalchemy/engine/default.py", line 588, in do_execute
     cursor.execute(statement, parameters)
 psycopg2.errors.UndefinedTable: relation "connection" does not exist
 LINE 2: FROM connection GROUP BY connection.conn_id
              ^
 
 
 The above exception was the direct cause of the following exception:
 
 Traceback (most recent call last):
   File "/home/airflow/.local/bin/airflow", line 37, in <module>
     args.func(args)
   File "/home/airflow/.local/lib/python3.6/site-packages/airflow/utils/cli.py", line 75, in wrapper
     return f(*args, **kwargs)
   File "/home/airflow/.local/lib/python3.6/site-packages/airflow/bin/cli.py", line 900, in webserver
     app = cached_app_rbac(None) if settings.RBAC else cached_app(None)
   File "/home/airflow/.local/lib/python3.6/site-packages/airflow/www/app.py", line 232, in cached_app
     app = create_app(config, testing)
   File "/home/airflow/.local/lib/python3.6/site-packages/airflow/www/app.py", line 87, in create_app
     from airflow.www import views
   File "/home/airflow/.local/lib/python3.6/site-packages/airflow/www/views.py", line 2477, in <module>
     class ChartModelView(wwwutils.DataProfilingMixin, AirflowModelView):
   File "/home/airflow/.local/lib/python3.6/site-packages/airflow/www/views.py", line 2568, in ChartModelView
     'conn_id': _connection_ids()
   File "/home/airflow/.local/lib/python3.6/site-packages/airflow/utils/db.py", line 74, in wrapper
     return func(*args, **kwargs)
   File "/home/airflow/.local/lib/python3.6/site-packages/airflow/www/views.py", line 2474, in _connection_ids
     .group_by(Connection.conn_id))]
   File "/home/airflow/.local/lib/python3.6/site-packages/sqlalchemy/orm/query.py", line 3403, in __iter__
     return self._execute_and_instances(context)
   File "/home/airflow/.local/lib/python3.6/site-packages/sqlalchemy/orm/query.py", line 3428, in _execute_and_instances
     result = conn.execute(querycontext.statement, self._params)
   File "/home/airflow/.local/lib/python3.6/site-packages/sqlalchemy/engine/base.py", line 984, in execute
     return meth(self, multiparams, params)
   File "/home/airflow/.local/lib/python3.6/site-packages/sqlalchemy/sql/elements.py", line 293, in _execute_on_connection
     return connection._execute_clauseelement(self, multiparams, params)
   File "/home/airflow/.local/lib/python3.6/site-packages/sqlalchemy/engine/base.py", line 1103, in _execute_clauseelement
     distilled_params,
   File "/home/airflow/.local/lib/python3.6/site-packages/sqlalchemy/engine/base.py", line 1288, in _execute_context
     e, statement, parameters, cursor, context
   File "/home/airflow/.local/lib/python3.6/site-packages/sqlalchemy/engine/base.py", line 1482, in _handle_dbapi_exception
     sqlalchemy_exception, with_traceback=exc_info[2], from_=e
   File "/home/airflow/.local/lib/python3.6/site-packages/sqlalchemy/util/compat.py", line 178, in raise_
     raise exception
   File "/home/airflow/.local/lib/python3.6/site-packages/sqlalchemy/engine/base.py", line 1248, in _execute_context
     cursor, statement, parameters, context
   File "/home/airflow/.local/lib/python3.6/site-packages/sqlalchemy/engine/default.py", line 588, in do_execute
     cursor.execute(statement, parameters)
 sqlalchemy.exc.ProgrammingError: (psycopg2.errors.UndefinedTable) relation "connection" does not exist
 LINE 2: FROM connection GROUP BY connection.conn_id
              ^
 
 [SQL: SELECT connection.conn_id AS connection_conn_id 
 FROM connection GROUP BY connection.conn_id]
 (Background on this error at: http://sqlalche.me/e/f405)
