 DB_BACKEND=postgresql+psycopg2
 DB_HOST=postgres
 DB_PORT=5432
 
 DB_BACKEND=postgresql+psycopg2
 DB_HOST=postgres
 DB_PORT=5432
 
 [2025-01-29 14:17:19,521] {cli_action_loggers.py:107} WARNING - Failed to log action with (psycopg2.errors.UndefinedTable) relation "log" does not exist
 LINE 1: INSERT INTO log (dttm, dag_id, task_id, event, execution_dat...
                     ^
 
 [SQL: INSERT INTO log (dttm, dag_id, task_id, event, execution_date, owner, extra) VALUES (%(dttm)s, %(dag_id)s, %(task_id)s, %(event)s, %(execution_date)s, %(owner)s, %(extra)s) RETURNING log.id]
 [parameters: {'dttm': datetime.datetime(2025, 1, 29, 14, 17, 19, 493583, tzinfo=<Timezone [UTC]>), 'dag_id': None, 'task_id': None, 'event': 'cli_scheduler', 'execution_date': None, 'owner': 'airflow', 'extra': '{"host_name": "3f0a5dda3f3a", "full_command": "[\'/home/airflow/.local/bin/airflow\', \'scheduler\']"}'}]
 (Background on this error at: http://sqlalche.me/e/f405)
   ____________       _____________
  ____    |__( )_________  __/__  /________      __
 ____  /| |_  /__  ___/_  /_ __  /_  __ \_ | /| / /
 ___  ___ |  / _  /   _  __/ _  / / /_/ /_ |/ |/ /
  _/_/  |_/_/  /_/    /_/    /_/  \____/____/|__/
 [2025-01-29 14:17:19,592] {__init__.py:51} INFO - Using executor CeleryExecutor
 Traceback (most recent call last):
   File "/home/airflow/.local/lib/python3.6/site-packages/sqlalchemy/engine/base.py", line 1248, in _execute_context
     cursor, statement, parameters, context
   File "/home/airflow/.local/lib/python3.6/site-packages/sqlalchemy/engine/default.py", line 588, in do_execute
     cursor.execute(statement, parameters)
 psycopg2.errors.UndefinedTable: relation "job" does not exist
 LINE 1: INSERT INTO job (dag_id, state, job_type, start_date, end_da...
                     ^
 
 
 The above exception was the direct cause of the following exception:
 
 Traceback (most recent call last):
   File "/home/airflow/.local/bin/airflow", line 37, in <module>
     args.func(args)
   File "/home/airflow/.local/lib/python3.6/site-packages/airflow/utils/cli.py", line 75, in wrapper
     return f(*args, **kwargs)
   File "/home/airflow/.local/lib/python3.6/site-packages/airflow/bin/cli.py", line 1040, in scheduler
     job.run()
   File "/home/airflow/.local/lib/python3.6/site-packages/airflow/jobs/base_job.py", line 215, in run
     session.commit()
   File "/home/airflow/.local/lib/python3.6/site-packages/sqlalchemy/orm/session.py", line 1036, in commit
     self.transaction.commit()
   File "/home/airflow/.local/lib/python3.6/site-packages/sqlalchemy/orm/session.py", line 503, in commit
     self._prepare_impl()
   File "/home/airflow/.local/lib/python3.6/site-packages/sqlalchemy/orm/session.py", line 482, in _prepare_impl
     self.session.flush()
   File "/home/airflow/.local/lib/python3.6/site-packages/sqlalchemy/orm/session.py", line 2496, in flush
     self._flush(objects)
   File "/home/airflow/.local/lib/python3.6/site-packages/sqlalchemy/orm/session.py", line 2637, in _flush
     transaction.rollback(_capture_exception=True)
   File "/home/airflow/.local/lib/python3.6/site-packages/sqlalchemy/util/langhelpers.py", line 69, in __exit__
     exc_value, with_traceback=exc_tb,
   File "/home/airflow/.local/lib/python3.6/site-packages/sqlalchemy/util/compat.py", line 178, in raise_
     raise exception
   File "/home/airflow/.local/lib/python3.6/site-packages/sqlalchemy/orm/session.py", line 2597, in _flush
     flush_context.execute()
   File "/home/airflow/.local/lib/python3.6/site-packages/sqlalchemy/orm/unitofwork.py", line 422, in execute
     rec.execute(self)
   File "/home/airflow/.local/lib/python3.6/site-packages/sqlalchemy/orm/unitofwork.py", line 589, in execute
     uow,
   File "/home/airflow/.local/lib/python3.6/site-packages/sqlalchemy/orm/persistence.py", line 245, in save_obj
     insert,
   File "/home/airflow/.local/lib/python3.6/site-packages/sqlalchemy/orm/persistence.py", line 1136, in _emit_insert_statements
     statement, params
   File "/home/airflow/.local/lib/python3.6/site-packages/sqlalchemy/engine/base.py", line 984, in execute
     return meth(self, multiparams, params)
   File "/home/airflow/.local/lib/python3.6/site-packages/sqlalchemy/sql/elements.py", line 293, in _execute_on_connection
     return connection._execute_clauseelement(self, multiparams, params)
   File "/home/airflow/.local/lib/python3.6/site-packages/sqlalchemy/engine/base.py", line 1103, in _execute_clauseelement
     distilled_params,
   File "/home/airflow/.local/lib/python3.6/site-packages/sqlalchemy/engine/base.py", line 1288, in _execute_context
     e, statement, parameters, cursor, context
   File "/home/airflow/.local/lib/python3.6/site-packages/sqlalchemy/engine/base.py", line 1482, in _handle_dbapi_exception
     sqlalchemy_exception, with_traceback=exc_info[2], from_=e
   File "/home/airflow/.local/lib/python3.6/site-packages/sqlalchemy/util/compat.py", line 178, in raise_
     raise exception
   File "/home/airflow/.local/lib/python3.6/site-packages/sqlalchemy/engine/base.py", line 1248, in _execute_context
     cursor, statement, parameters, context
   File "/home/airflow/.local/lib/python3.6/site-packages/sqlalchemy/engine/default.py", line 588, in do_execute
     cursor.execute(statement, parameters)
 sqlalchemy.exc.ProgrammingError: (psycopg2.errors.UndefinedTable) relation "job" does not exist
 LINE 1: INSERT INTO job (dag_id, state, job_type, start_date, end_da...
                     ^
 
 [SQL: INSERT INTO job (dag_id, state, job_type, start_date, end_date, latest_heartbeat, executor_class, hostname, unixname) VALUES (%(dag_id)s, %(state)s, %(job_type)s, %(start_date)s, %(end_date)s, %(latest_heartbeat)s, %(executor_class)s, %(hostname)s, %(unixname)s) RETURNING job.id]
 [parameters: {'dag_id': None, 'state': 'running', 'job_type': 'SchedulerJob', 'start_date': datetime.datetime(2025, 1, 29, 14, 17, 19, 594436, tzinfo=<Timezone [UTC]>), 'end_date': None, 'latest_heartbeat': datetime.datetime(2025, 1, 29, 14, 17, 19, 594503, tzinfo=<Timezone [UTC]>), 'executor_class': 'NoneType', 'hostname': '3f0a5dda3f3a', 'unixname': 'airflow'}]
 (Background on this error at: http://sqlalche.me/e/f405)
